<?xml version="1.0" encoding="utf-8"?>
<!-- This URDF was automatically created by SolidWorks to URDF Exporter! Originally created by Stephen Brawner (brawner@gmail.com) 
     Commit Version: 1.6.0-4-g7f85cfe  Build Version: 1.6.7995.38578
     For more information, please see http://wiki.ros.org/sw_urdf_exporter -->
<robot
  name="y2_description">
  <link
    name="base_link">
<inertial>
  <origin
    xyz="0.0 0.0 0.00660336"
    rpy="0 0 0" />
  <mass
    value="13.62220311" />
  <inertia
    ixx="0.05745341"
    ixy="-0.0002082"
    ixz="0.0"
    iyy="0.28193067"
    iyz="0.0"
    izz="0.28070589" />
</inertial>
    <visual>
      <origin
        xyz="0 0 0"
        rpy="0 0 0" />
      <geometry>
        <mesh
          filename="../meshes/base_link.STL" />
      </geometry>
      <material
        name="">
        <color
          rgba="0.75294 0.75294 0.75294 1" />
      </material>
    </visual>
    <collision>
      <origin
        xyz="0 0 0"
        rpy="0 0 0" />
      <geometry>
        <mesh
          filename="../meshes/base_link.STL" />
      </geometry>
    </collision>
  </link>
  <link
    name="imu_link">
<inertial>
  <origin
    xyz="0 0 0"
    rpy="0 0 0" />
  <mass
    value="0.001" />
  <inertia
    ixx="0.0001"
    ixy="0"
    ixz="0"
    iyy="0.0001"
    iyz="0"
    izz="0.0001" />
</inertial>
    <visual>
      <origin
        xyz="0 0 0"
        rpy="0 0 0" />
      <geometry>
        <box
          size="0.001 0.001 0.001" />
      </geometry>
      <material
        name="red">
        <color
          rgba="1 0 0 1" />
      </material>
    </visual>
    <collision>
      <origin
        xyz="0 0 0"
        rpy="0 0 0" />
      <geometry>
        <box
          size="0.000518 0.000518 0.000518" />
      </geometry>
    </collision>
  </link>
  <joint
    name="imu_joint"
    type="fixed">
    <origin
      xyz="0 0 0"
      rpy="0 0 0" />
    <parent
      link="base_link" />
    <child
      link="imu_link" />
  </joint>
  <link
    name="front_left_hip_link">
<inertial>
  <origin
    xyz="-0.00557137 3.365e-05 0.05740371"
    rpy="0 0 0" />
  <mass
    value="0.93241215" />
  <inertia
    ixx="0.0011636"
    ixy="-4.5e-07"
    ixz="7.77e-06"
    iyy="0.00081261"
    iyz="1.34e-06"
    izz="0.00072333" />
</inertial>
    <visual>
      <origin
        xyz="0 0 0"
        rpy="0 0 0" />
      <geometry>
        <mesh
          filename="../meshes/front_left_hip_link.STL" />
      </geometry>
      <material
        name="">
        <color
          rgba="0.75294 0.75294 0.75294 1" />
      </material>
    </visual>
    <collision>
      <origin
        xyz="0 0 0"
        rpy="0 0 0" />
      <geometry>
        <mesh
          filename="../meshes/front_left_hip_link.STL" />
      </geometry>
    </collision>
  </link>
  <joint
    name="front_left_hip_joint"
    type="fixed">
    <origin
      xyz="0.126 0.0525 0"
      rpy="1.5708 0 1.5708" />
    <parent
      link="base_link" />
    <child
      link="front_left_hip_link" />
  </joint>
  <link
    name="front_left_thigh_link">
<inertial>
  <origin
    xyz="0.00850956 0.00116386 -0.03650107"
    rpy="0 0 0" />
  <mass
    value="1.04795802" />
  <inertia
    ixx="0.00097197"
    ixy="-0.00013838"
    ixz="-0.00028846"
    iyy="0.00202121"
    iyz="-4.168e-05"
    izz="0.0022969" />
</inertial>
    <visual>
      <origin
        xyz="0 0 0"
        rpy="0 0 0" />
      <geometry>
        <mesh
          filename="../meshes/front_left_thigh_link.STL" />
      </geometry>
      <material
        name="">
        <color
          rgba="0.75294 0.75294 0.75294 1" />
      </material>
    </visual>
    <collision>
      <origin
        xyz="0 0 0"
        rpy="0 0 0" />
      <geometry>
        <mesh
          filename="../meshes/front_left_thigh_link.STL" />
      </geometry>
    </collision>
  </link>
  <joint
    name="front_left_thigh_joint"
    type="revolute">
    <origin
      xyz="0.087 0 0.0583"
      rpy="-1.5708 0.7854 -1.5708" />
    <parent
      link="front_left_hip_link" />
    <child
      link="front_left_thigh_link" />
    <axis
      xyz="0 0 1" />
    <limit
      lower="-2.3562"
      upper="2.3562"
      effort="24"
      velocity="6" />
  </joint>
  <link
    name="front_left_knee_link">
<inertial>
  <origin
    xyz="0.08449172 0.00209534 -0.00687557"
    rpy="0 0 0" />
  <mass
    value="0.19539429" />
  <inertia
    ixx="6.436e-05"
    ixy="5.555e-05"
    ixz="-3.65e-05"
    iyy="0.0008211"
    iyz="3.3e-07"
    izz="0.0008554" />
</inertial>
    <visual>
      <origin
        xyz="0 0 0"
        rpy="0 0 0" />
      <geometry>
        <mesh
          filename="../meshes/front_left_knee_link.STL" />
      </geometry>
      <material
        name="">
        <color
          rgba="0.75294 0.75294 0.75294 1" />
      </material>
    </visual>
    <collision>
      <origin
        xyz="0 0 0"
        rpy="0 0 0" />
      <geometry>
        <mesh
          filename="../meshes/front_left_knee_link.STL" />
      </geometry>
    </collision>
  </link>
  <joint
    name="front_left_knee_joint"
    type="revolute">
    <origin
      xyz="0.18 0 0"
      rpy="0 0 -2.5197" />
    <parent
      link="front_left_thigh_link" />
    <child
      link="front_left_knee_link" />
    <axis
      xyz="0 0 1" />
    <limit
      lower="0"
      upper="1.9199"
      effort="24"
      velocity="6" />
  </joint>
  <link
    name="front_left_wheel_link">
<inertial>
  <origin
    xyz="-1.864e-05 1.98e-06 0.03424961"
    rpy="0 0 0" />
  <mass
    value="1.48448049" />
  <inertia
    ixx="0.00350856"
    ixy="3e-08"
    ixz="2.2e-07"
    iyy="0.00351161"
    iyz="-2.2e-07"
    izz="0.00660183" />
</inertial>
    <visual>
      <origin
        xyz="0 0 0"
        rpy="0 0 0" />
      <geometry>
        <mesh
          filename="../meshes/front_left_wheel_link.STL" />
      </geometry>
      <material
        name="">
        <color
          rgba="0.89804 0.91765 0.92941 1" />
      </material>
    </visual>
    <collision>
      <origin
        xyz="0 0 0"
        rpy="0 0 0" />
      <geometry>
        <mesh
          filename="../meshes/front_left_wheel_link.STL" />
      </geometry>
    </collision>
  </link>
  <joint
    name="front_left_wheel_joint"
    type="revolute">
    <origin
      xyz="0.18 0 0"
      rpy="0 0 0.16348" />
    <parent
      link="front_left_knee_link" />
    <child
      link="front_left_wheel_link" />
    <axis
      xyz="0 0 1" />
    <limit
      lower="-31415926535.0"
      upper="31415926535.0"
      effort="20"
      velocity="30" />
  </joint>
  <link
    name="front_right_hip_link">
<inertial>
  <origin
    xyz="0.00557137 -3.365e-05 0.05740371"
    rpy="0 0 0" />
  <mass
    value="0.93241215" />
  <inertia
    ixx="0.0011636"
    ixy="-4.5e-07"
    ixz="-7.77e-06"
    iyy="0.00081261"
    iyz="-1.34e-06"
    izz="0.00072333" />
</inertial>
    <visual>
      <origin
        xyz="0 0 0"
        rpy="0 0 0" />
      <geometry>
        <mesh
          filename="../meshes/front_right_hip_link.STL" />
      </geometry>
      <material
        name="">
        <color
          rgba="0.75294 0.75294 0.75294 1" />
      </material>
    </visual>
    <collision>
      <origin
        xyz="0 0 0"
        rpy="0 0 0" />
      <geometry>
        <mesh
          filename="../meshes/front_right_hip_link.STL" />
      </geometry>
    </collision>
  </link>
  <joint
    name="front_right_hip_joint"
    type="fixed">
    <origin
      xyz="0.126 -0.0525 0"
      rpy="1.5708 0 1.5708" />
    <parent
      link="base_link" />
    <child
      link="front_right_hip_link" />
  </joint>
  <link
    name="front_right_thigh_link">
<inertial>
  <origin
    xyz="0.00850956 0.00116386 0.03650107"
    rpy="0 0 0" />
  <mass
    value="1.04795802" />
  <inertia
    ixx="0.00097197"
    ixy="-0.00013838"
    ixz="0.00028846"
    iyy="0.00202121"
    iyz="4.168e-05"
    izz="0.0022969" />
</inertial>
    <visual>
      <origin
        xyz="0 0 0"
        rpy="0 0 0" />
      <geometry>
        <mesh
          filename="../meshes/front_right_thigh_link.STL" />
      </geometry>
      <material
        name="">
        <color
          rgba="0.75294 0.75294 0.75294 1" />
      </material>
    </visual>
    <collision>
      <origin
        xyz="0 0 0"
        rpy="0 0 0" />
      <geometry>
        <mesh
          filename="../meshes/front_right_thigh_link.STL" />
      </geometry>
    </collision>
  </link>
  <joint
    name="front_right_thigh_joint"
    type="revolute">
    <origin
      xyz="-0.087 0 0.0583"
      rpy="-1.5708 0.7854 -1.5708" />
    <parent
      link="front_right_hip_link" />
    <child
      link="front_right_thigh_link" />
    <axis
      xyz="0 0 1" />
    <limit
      lower="-2.3562"
      upper="2.3562"
      effort="24"
      velocity="6" />
  </joint>
  <link
    name="front_right_knee_link">
<inertial>
  <origin
    xyz="0.08449172 0.00209534 0.00687557"
    rpy="0 0 0" />
  <mass
    value="0.19539429" />
  <inertia
    ixx="6.436e-05"
    ixy="5.555e-05"
    ixz="3.65e-05"
    iyy="0.0008211"
    iyz="-3.3e-07"
    izz="0.0008554" />
</inertial>
    <visual>
      <origin
        xyz="0 0 0"
        rpy="0 0 0" />
      <geometry>
        <mesh
          filename="../meshes/front_right_knee_link.STL" />
      </geometry>
      <material
        name="">
        <color
          rgba="0.75294 0.75294 0.75294 1" />
      </material>
    </visual>
    <collision>
      <origin
        xyz="0 0 0"
        rpy="0 0 0" />
      <geometry>
        <mesh
          filename="../meshes/front_right_knee_link.STL" />
      </geometry>
    </collision>
  </link>
  <joint
    name="front_right_knee_joint"
    type="revolute">
    <origin
      xyz="0.18 0 0"
      rpy="0 0 -2.5197" />
    <parent
      link="front_right_thigh_link" />
    <child
      link="front_right_knee_link" />
    <axis
      xyz="0 0 1" />
    <limit
      lower="0"
      upper="1.9199"
      effort="24"
      velocity="6" />
  </joint>
  <link
    name="front_right_wheel_link">
<inertial>
  <origin
    xyz="-1.864e-05 1.98e-06 -0.03424961"
    rpy="0 0 0" />
  <mass
    value="1.48448049" />
  <inertia
    ixx="0.00350856"
    ixy="3e-08"
    ixz="-2.2e-07"
    iyy="0.00351161"
    iyz="-2.2e-07"
    izz="0.00660183" />
</inertial>
    <visual>
      <origin
        xyz="0 0 0"
        rpy="0 0 0" />
      <geometry>
        <mesh
          filename="../meshes/front_right_wheel_link.STL" />
      </geometry>
      <material
        name="">
        <color
          rgba="0.89804 0.91765 0.92941 1" />
      </material>
    </visual>
    <collision>
      <origin
        xyz="0 0 0"
        rpy="0 0 0" />
      <geometry>
        <mesh
          filename="../meshes/front_right_wheel_link.STL" />
      </geometry>
    </collision>
  </link>
  <joint
    name="front_right_wheel_joint"
    type="revolute">
    <origin
      xyz="0.18 0 0"
      rpy="0 0 0.16348" />
    <parent
      link="front_right_knee_link" />
    <child
      link="front_right_wheel_link" />
    <axis
      xyz="0 0 1" />
    <limit
      lower="-31415926535"
      upper="31415926535"
      effort="20"
      velocity="30" />
  </joint>
  <link
    name="back_left_hip_link">
<inertial>
  <origin
    xyz="-0.00557137 3.365e-05 -0.05740371"
    rpy="0 0 0" />
  <mass
    value="0.93241215" />
  <inertia
    ixx="0.0011636"
    ixy="-4.5e-07"
    ixz="-7.77e-06"
    iyy="0.00081261"
    iyz="-1.34e-06"
    izz="0.00072333" />
</inertial>
    <visual>
      <origin
        xyz="0 0 0"
        rpy="0 0 0" />
      <geometry>
        <mesh
          filename="../meshes/back_left_hip_link.STL" />
      </geometry>
      <material
        name="">
        <color
          rgba="0.75294 0.75294 0.75294 1" />
      </material>
    </visual>
    <collision>
      <origin
        xyz="0 0 0"
        rpy="0 0 0" />
      <geometry>
        <mesh
          filename="../meshes/back_left_hip_link.STL" />
      </geometry>
    </collision>
  </link>
  <joint
    name="back_left_hip_joint"
    type="fixed">
    <origin
      xyz="-0.126 0.0525 0"
      rpy="1.5708 0 1.5708" />
    <parent
      link="base_link" />
    <child
      link="back_left_hip_link" />
  </joint>
  <link
    name="back_left_thigh_link">
<inertial>
  <origin
    xyz="0.00850956 -0.00116386 -0.03650107"
    rpy="0 0 0" />
  <mass
    value="1.04795802" />
  <inertia
    ixx="0.00097197"
    ixy="0.00013838"
    ixz="-0.00028846"
    iyy="0.00202121"
    iyz="4.168e-05"
    izz="0.0022969" />
</inertial>
    <visual>
      <origin
        xyz="0 0 0"
        rpy="0 0 0" />
      <geometry>
        <mesh
          filename="../meshes/back_left_thigh_link.STL" />
      </geometry>
      <material
        name="">
        <color
          rgba="0.75294 0.75294 0.75294 1" />
      </material>
    </visual>
    <collision>
      <origin
        xyz="0 0 0"
        rpy="0 0 0" />
      <geometry>
        <mesh
          filename="../meshes/back_left_thigh_link.STL" />
      </geometry>
    </collision>
  </link>
  <joint
    name="back_left_thigh_joint"
    type="revolute">
    <origin
      xyz="0.087 0 -0.0583"
      rpy="-1.5708 -0.7854 -1.5708" />
    <parent
      link="back_left_hip_link" />
    <child
      link="back_left_thigh_link" />
    <axis
      xyz="0 0 1" />
    <limit
      lower="-2.3562"
      upper="2.3562"
      effort="24"
      velocity="6" />
  </joint>
  <link
    name="back_left_knee_link">
<inertial>
  <origin
    xyz="0.08449171 -0.00209534 -0.00687557"
    rpy="0 0 0" />
  <mass
    value="0.19539429" />
  <inertia
    ixx="6.436e-05"
    ixy="-5.555e-05"
    ixz="-3.65e-05"
    iyy="0.0008211"
    iyz="-3.3e-07"
    izz="0.0008554" />
</inertial>
    <visual>
      <origin
        xyz="0 0 0"
        rpy="0 0 0" />
      <geometry>
        <mesh
          filename="../meshes/back_left_knee_link.STL" />
      </geometry>
      <material
        name="">
        <color
          rgba="0.75294 0.75294 0.75294 1" />
      </material>
    </visual>
    <collision>
      <origin
        xyz="0 0 0"
        rpy="0 0 0" />
      <geometry>
        <mesh
          filename="../meshes/back_left_knee_link.STL" />
      </geometry>
    </collision>
  </link>
  <joint
    name="back_left_knee_joint"
    type="revolute">
    <origin
      xyz="0.18 0 0"
      rpy="0 0 2.5197" />
    <parent
      link="back_left_thigh_link" />
    <child
      link="back_left_knee_link" />
    <axis
      xyz="0 0 1" />
    <limit
      lower="-1.9199"
      upper="0"
      effort="24"
      velocity="6" />
  </joint>
  <link
    name="back_left_wheel_link">
<inertial>
  <origin
    xyz="-1.864e-05 -1.98e-06 0.03424961"
    rpy="0 0 0" />
  <mass
    value="1.48448049" />
  <inertia
    ixx="0.00350856"
    ixy="-3e-08"
    ixz="2.2e-07"
    iyy="0.00351161"
    iyz="2.2e-07"
    izz="0.00660183" />
</inertial>
    <visual>
      <origin
        xyz="0 0 0"
        rpy="0 0 0" />
      <geometry>
        <mesh
          filename="../meshes/back_left_wheel_link.STL" />
      </geometry>
      <material
        name="">
        <color
          rgba="1 1 1 1" />
      </material>
    </visual>
    <collision>
      <origin
        xyz="0 0 0"
        rpy="0 0 0" />
      <geometry>
        <mesh
          filename="../meshes/back_left_wheel_link.STL" />
      </geometry>
    </collision>
  </link>
  <joint
    name="back_left_wheel_joint"
    type="revolute">
    <origin
      xyz="0.18 0 0"
      rpy="0 0 2.9781" />
    <parent
      link="back_left_knee_link" />
    <child
      link="back_left_wheel_link" />
    <axis
      xyz="0 0 1" />
    <limit
      lower="-31415926535"
      upper="31415926535"
      effort="20"
      velocity="30" />
  </joint>
  <link
    name="back_right_hip_link">
<inertial>
  <origin
    xyz="0.00557137 3.365e-05 -0.05740371"
    rpy="0 0 0" />
  <mass
    value="0.93241215" />
  <inertia
    ixx="0.0011636"
    ixy="4.5e-07"
    ixz="7.77e-06"
    iyy="0.00081261"
    iyz="-1.34e-06"
    izz="0.00072333" />
</inertial>
    <visual>
      <origin
        xyz="0 0 0"
        rpy="0 0 0" />
      <geometry>
        <mesh
          filename="../meshes/back_right_hip_link.STL" />
      </geometry>
      <material
        name="">
        <color
          rgba="0.75294 0.75294 0.75294 1" />
      </material>
    </visual>
    <collision>
      <origin
        xyz="0 0 0"
        rpy="0 0 0" />
      <geometry>
        <mesh
          filename="../meshes/back_right_hip_link.STL" />
      </geometry>
    </collision>
  </link>
  <joint
    name="back_right_hip_joint"
    type="fixed">
    <origin
      xyz="-0.126 -0.0525 0"
      rpy="1.5708 0 1.5708" />
    <parent
      link="base_link" />
    <child
      link="back_right_hip_link" />
  </joint>
  <link
    name="back_right_thigh_link">
<inertial>
  <origin
    xyz="0.00850956 -0.00116386 0.03650107"
    rpy="0 0 0" />
  <mass
    value="1.04795802" />
  <inertia
    ixx="0.00097197"
    ixy="0.00013838"
    ixz="0.00028846"
    iyy="0.00202121"
    iyz="-4.168e-05"
    izz="0.0022969" />
</inertial>
    <visual>
      <origin
        xyz="0 0 0"
        rpy="0 0 0" />
      <geometry>
        <mesh
          filename="../meshes/back_right_thigh_link.STL" />
      </geometry>
      <material
        name="">
        <color
          rgba="0.75294 0.75294 0.75294 1" />
      </material>
    </visual>
    <collision>
      <origin
        xyz="0 0 0"
        rpy="0 0 0" />
      <geometry>
        <mesh
          filename="../meshes/back_right_thigh_link.STL" />
      </geometry>
    </collision>
  </link>
  <joint
    name="back_right_thigh_joint"
    type="revolute">
    <origin
      xyz="-0.087 0 -0.0583"
      rpy="-1.5708 -0.7854 -1.5708" />
    <parent
      link="back_right_hip_link" />
    <child
      link="back_right_thigh_link" />
    <axis
      xyz="0 0 1" />
    <limit
      lower="-2.3562"
      upper="2.3562"
      effort="24"
      velocity="6" />
  </joint>
  <link
    name="back_right_knee_link">
<inertial>
  <origin
    xyz="0.08449171 -0.00209534 0.00687557"
    rpy="0 0 0" />
  <mass
    value="0.19539429" />
  <inertia
    ixx="6.436e-05"
    ixy="-5.555e-05"
    ixz="3.65e-05"
    iyy="0.0008211"
    iyz="3.3e-07"
    izz="0.0008554" />
</inertial>
    <visual>
      <origin
        xyz="0 0 0"
        rpy="0 0 0" />
      <geometry>
        <mesh
          filename="../meshes/back_right_knee_link.STL" />
      </geometry>
      <material
        name="">
        <color
          rgba="0.75294 0.75294 0.75294 1" />
      </material>
    </visual>
    <collision>
      <origin
        xyz="0 0 0"
        rpy="0 0 0" />
      <geometry>
        <mesh
          filename="../meshes/back_right_knee_link.STL" />
      </geometry>
    </collision>
  </link>
  <joint
    name="back_right_knee_joint"
    type="revolute">
    <origin
      xyz="0.18 0 0"
      rpy="0 0 2.5197" />
    <parent
      link="back_right_thigh_link" />
    <child
      link="back_right_knee_link" />
    <axis
      xyz="0 0 1" />
    <limit
      lower="-1.9199"
      upper="0"
      effort="24"
      velocity="6" />
  </joint>
  <link
    name="back_right_wheel_link">
<inertial>
  <origin
    xyz="-1.864e-05 -1.98e-06 -0.03424961"
    rpy="0 0 0" />
  <mass
    value="1.48448049" />
  <inertia
    ixx="0.00350856"
    ixy="-3e-08"
    ixz="-2.2e-07"
    iyy="0.00351161"
    iyz="-2.2e-07"
    izz="0.00660183" />
</inertial>
    <visual>
      <origin
        xyz="0 0 0"
        rpy="0 0 0" />
      <geometry>
        <mesh
          filename="../meshes/back_right_wheel_link.STL" />
      </geometry>
      <material
        name="">
        <color
          rgba="0.89804 0.91765 0.92941 1" />
      </material>
    </visual>
    <collision>
      <origin
        xyz="0 0 0"
        rpy="0 0 0" />
      <geometry>
        <mesh
          filename="../meshes/back_right_wheel_link.STL" />
      </geometry>
    </collision>
  </link>
  <joint
    name="back_right_wheel_joint"
    type="revolute">
    <origin
      xyz="0.18 0 0"
      rpy="0 0 2.9781" />
    <parent
      link="back_right_knee_link" />
    <child
      link="back_right_wheel_link" />
    <axis
      xyz="0 0 1" />
    <limit
      lower="-31415926535"
      upper="31415926535"
      effort="20"
      velocity="30" />
  </joint>
</robot>
